2025-09-05 11:56:07,579 (__init__.py:1115 MainThread) ERROR - TeleBot: "Infinity polling exception: HTTPSConnectionPool(host='api.telegram.org', port=443): Max retries exceeded with url: /bot8485995133:***********************************/getMe (Caused by NewConnectionError('<urllib3.connection.HTTPSConnection object at 0x7680a82990>: Failed to establish a new connection: [Errno 7] No address associated with hostname'))"
2025-09-05 11:56:07,605 (__init__.py:1117 MainThread) ERROR - TeleBot: "Exception traceback:
Traceback (most recent call last):
  File "/data/data/com.termux/files/usr/lib/python3.12/site-packages/urllib3/connection.py", line 169, in _new_conn
    conn = connection.create_connection(
           ^^^^^^^^^^^^^^^^^^^^^^^^^^^^^
  File "/data/data/com.termux/files/usr/lib/python3.12/site-packages/urllib3/util/connection.py", line 73, in create_connection
    for res in socket.getaddrinfo(host, port, family, socket.SOCK_STREAM):
               ^^^^^^^^^^^^^^^^^^^^^^^^^^^^^^^^^^^^^^^^^^^^^^^^^^^^^^^^^^
  File "/data/data/com.termux/files/usr/lib/python3.12/socket.py", line 978, in getaddrinfo
    for res in _socket.getaddrinfo(host, port, family, type, proto, flags):
               ^^^^^^^^^^^^^^^^^^^^^^^^^^^^^^^^^^^^^^^^^^^^^^^^^^^^^^^^^^^
socket.gaierror: [Errno 7] No address associated with hostname

During handling of the above exception, another exception occurred:

Traceback (most recent call last):
  File "/data/data/com.termux/files/usr/lib/python3.12/site-packages/urllib3/connectionpool.py", line 699, in urlopen
    httplib_response = self._make_request(
                       ^^^^^^^^^^^^^^^^^^^
  File "/data/data/com.termux/files/usr/lib/python3.12/site-packages/urllib3/connectionpool.py", line 382, in _make_request
    self._validate_conn(conn)
  File "/data/data/com.termux/files/usr/lib/python3.12/site-packages/urllib3/connectionpool.py", line 1010, in _validate_conn
    conn.connect()
  File "/data/data/com.termux/files/usr/lib/python3.12/site-packages/urllib3/connection.py", line 353, in connect
    conn = self._new_conn()
           ^^^^^^^^^^^^^^^^
  File "/data/data/com.termux/files/usr/lib/python3.12/site-packages/urllib3/connection.py", line 181, in _new_conn
    raise NewConnectionError(
urllib3.exceptions.NewConnectionError: <urllib3.connection.HTTPSConnection object at 0x7680a82990>: Failed to establish a new connection: [Errno 7] No address associated with hostname

During handling of the above exception, another exception occurred:

Traceback (most recent call last):
  File "/data/data/com.termux/files/usr/lib/python3.12/site-packages/requests/adapters.py", line 644, in send
    resp = conn.urlopen(
           ^^^^^^^^^^^^^
  File "/data/data/com.termux/files/usr/lib/python3.12/site-packages/urllib3/connectionpool.py", line 755, in urlopen
    retries = retries.increment(
              ^^^^^^^^^^^^^^^^^^
  File "/data/data/com.termux/files/usr/lib/python3.12/site-packages/urllib3/util/retry.py", line 574, in increment
    raise MaxRetryError(_pool, url, error or ResponseError(cause))
urllib3.exceptions.MaxRetryError: HTTPSConnectionPool(host='api.telegram.org', port=443): Max retries exceeded with url: /bot8485995133:***********************************/getMe (Caused by NewConnectionError('<urllib3.connection.HTTPSConnection object at 0x7680a82990>: Failed to establish a new connection: [Errno 7] No address associated with hostname'))

During handling of the above exception, another exception occurred:

Traceback (most recent call last):
  File "/data/data/com.termux/files/usr/lib/python3.12/site-packages/telebot/__init__.py", line 1110, in infinity_polling
    self.polling(non_stop=True, timeout=timeout, long_polling_timeout=long_polling_timeout,
  File "/data/data/com.termux/files/usr/lib/python3.12/site-packages/telebot/__init__.py", line 1195, in polling
    logger.info('Starting your bot with username: [@%s]', self.user.username)
                                                          ^^^^^^^^^
  File "/data/data/com.termux/files/usr/lib/python3.12/site-packages/telebot/__init__.py", line 306, in user
    self._user = self.get_me()
                 ^^^^^^^^^^^^^
  File "/data/data/com.termux/files/usr/lib/python3.12/site-packages/telebot/__init__.py", line 1382, in get_me
    apihelper.get_me(self.token)
  File "/data/data/com.termux/files/usr/lib/python3.12/site-packages/telebot/apihelper.py", line 202, in get_me
    return _make_request(token, method_url)
           ^^^^^^^^^^^^^^^^^^^^^^^^^^^^^^^^
  File "/data/data/com.termux/files/usr/lib/python3.12/site-packages/telebot/apihelper.py", line 162, in _make_request
    result = _get_req_session().request(
             ^^^^^^^^^^^^^^^^^^^^^^^^^^^
  File "/data/data/com.termux/files/usr/lib/python3.12/site-packages/requests/sessions.py", line 589, in request
    resp = self.send(prep, **send_kwargs)
           ^^^^^^^^^^^^^^^^^^^^^^^^^^^^^^
  File "/data/data/com.termux/files/usr/lib/python3.12/site-packages/requests/sessions.py", line 703, in send
    r = adapter.send(request, **kwargs)
        ^^^^^^^^^^^^^^^^^^^^^^^^^^^^^^^
  File "/data/data/com.termux/files/usr/lib/python3.12/site-packages/requests/adapters.py", line 677, in send
    raise ConnectionError(e, request=request)
requests.exceptions.ConnectionError: HTTPSConnectionPool(host='api.telegram.org', port=443): Max retries exceeded with url: /bot8485995133:***********************************/getMe (Caused by NewConnectionError('<urllib3.connection.HTTPSConnection object at 0x7680a82990>: Failed to establish a new connection: [Errno 7] No address associated with hostname'))
"
2025-09-05 11:56:20,623 (__init__.py:1115 MainThread) ERROR - TeleBot: "Infinity polling exception: HTTPSConnectionPool(host='api.telegram.org', port=443): Max retries exceeded with url: /bot8485995133:***********************************/getMe (Caused by NewConnectionError('<urllib3.connection.HTTPSConnection object at 0x7680553440>: Failed to establish a new connection: [Errno 7] No address associated with hostname'))"
2025-09-05 11:56:20,641 (__init__.py:1117 MainThread) ERROR - TeleBot: "Exception traceback:
Traceback (most recent call last):
  File "/data/data/com.termux/files/usr/lib/python3.12/site-packages/urllib3/connection.py", line 169, in _new_conn
    conn = connection.create_connection(
           ^^^^^^^^^^^^^^^^^^^^^^^^^^^^^
  File "/data/data/com.termux/files/usr/lib/python3.12/site-packages/urllib3/util/connection.py", line 73, in create_connection
    for res in socket.getaddrinfo(host, port, family, socket.SOCK_STREAM):
               ^^^^^^^^^^^^^^^^^^^^^^^^^^^^^^^^^^^^^^^^^^^^^^^^^^^^^^^^^^
  File "/data/data/com.termux/files/usr/lib/python3.12/socket.py", line 978, in getaddrinfo
    for res in _socket.getaddrinfo(host, port, family, type, proto, flags):
               ^^^^^^^^^^^^^^^^^^^^^^^^^^^^^^^^^^^^^^^^^^^^^^^^^^^^^^^^^^^
socket.gaierror: [Errno 7] No address associated with hostname

During handling of the above exception, another exception occurred:

Traceback (most recent call last):
  File "/data/data/com.termux/files/usr/lib/python3.12/site-packages/urllib3/connectionpool.py", line 699, in urlopen
    httplib_response = self._make_request(
                       ^^^^^^^^^^^^^^^^^^^
  File "/data/data/com.termux/files/usr/lib/python3.12/site-packages/urllib3/connectionpool.py", line 382, in _make_request
    self._validate_conn(conn)
  File "/data/data/com.termux/files/usr/lib/python3.12/site-packages/urllib3/connectionpool.py", line 1010, in _validate_conn
    conn.connect()
  File "/data/data/com.termux/files/usr/lib/python3.12/site-packages/urllib3/connection.py", line 353, in connect
    conn = self._new_conn()
           ^^^^^^^^^^^^^^^^
  File "/data/data/com.termux/files/usr/lib/python3.12/site-packages/urllib3/connection.py", line 181, in _new_conn
    raise NewConnectionError(
urllib3.exceptions.NewConnectionError: <urllib3.connection.HTTPSConnection object at 0x7680553440>: Failed to establish a new connection: [Errno 7] No address associated with hostname

During handling of the above exception, another exception occurred:

Traceback (most recent call last):
  File "/data/data/com.termux/files/usr/lib/python3.12/site-packages/requests/adapters.py", line 644, in send
    resp = conn.urlopen(
           ^^^^^^^^^^^^^
  File "/data/data/com.termux/files/usr/lib/python3.12/site-packages/urllib3/connectionpool.py", line 755, in urlopen
    retries = retries.increment(
              ^^^^^^^^^^^^^^^^^^
  File "/data/data/com.termux/files/usr/lib/python3.12/site-packages/urllib3/util/retry.py", line 574, in increment
    raise MaxRetryError(_pool, url, error or ResponseError(cause))
urllib3.exceptions.MaxRetryError: HTTPSConnectionPool(host='api.telegram.org', port=443): Max retries exceeded with url: /bot8485995133:***********************************/getMe (Caused by NewConnectionError('<urllib3.connection.HTTPSConnection object at 0x7680553440>: Failed to establish a new connection: [Errno 7] No address associated with hostname'))

During handling of the above exception, another exception occurred:

Traceback (most recent call last):
  File "/data/data/com.termux/files/usr/lib/python3.12/site-packages/telebot/__init__.py", line 1110, in infinity_polling
    self.polling(non_stop=True, timeout=timeout, long_polling_timeout=long_polling_timeout,
  File "/data/data/com.termux/files/usr/lib/python3.12/site-packages/telebot/__init__.py", line 1195, in polling
    logger.info('Starting your bot with username: [@%s]', self.user.username)
                                                          ^^^^^^^^^
  File "/data/data/com.termux/files/usr/lib/python3.12/site-packages/telebot/__init__.py", line 306, in user
    self._user = self.get_me()
                 ^^^^^^^^^^^^^
  File "/data/data/com.termux/files/usr/lib/python3.12/site-packages/telebot/__init__.py", line 1382, in get_me
    apihelper.get_me(self.token)
  File "/data/data/com.termux/files/usr/lib/python3.12/site-packages/telebot/apihelper.py", line 202, in get_me
    return _make_request(token, method_url)
           ^^^^^^^^^^^^^^^^^^^^^^^^^^^^^^^^
  File "/data/data/com.termux/files/usr/lib/python3.12/site-packages/telebot/apihelper.py", line 162, in _make_request
    result = _get_req_session().request(
             ^^^^^^^^^^^^^^^^^^^^^^^^^^^
  File "/data/data/com.termux/files/usr/lib/python3.12/site-packages/requests/sessions.py", line 589, in request
    resp = self.send(prep, **send_kwargs)
           ^^^^^^^^^^^^^^^^^^^^^^^^^^^^^^
  File "/data/data/com.termux/files/usr/lib/python3.12/site-packages/requests/sessions.py", line 703, in send
    r = adapter.send(request, **kwargs)
        ^^^^^^^^^^^^^^^^^^^^^^^^^^^^^^^
  File "/data/data/com.termux/files/usr/lib/python3.12/site-packages/requests/adapters.py", line 677, in send
    raise ConnectionError(e, request=request)
requests.exceptions.ConnectionError: HTTPSConnectionPool(host='api.telegram.org', port=443): Max retries exceeded with url: /bot8485995133:***********************************/getMe (Caused by NewConnectionError('<urllib3.connection.HTTPSConnection object at 0x7680553440>: Failed to establish a new connection: [Errno 7] No address associated with hostname'))
"
2025-09-05 11:56:33,663 (__init__.py:1115 MainThread) ERROR - TeleBot: "Infinity polling exception: HTTPSConnectionPool(host='api.telegram.org', port=443): Max retries exceeded with url: /bot8485995133:***********************************/getMe (Caused by NewConnectionError('<urllib3.connection.HTTPSConnection object at 0x7680a82990>: Failed to establish a new connection: [Errno 7] No address associated with hostname'))"
2025-09-05 11:56:33,698 (__init__.py:1117 MainThread) ERROR - TeleBot: "Exception traceback:
Traceback (most recent call last):
  File "/data/data/com.termux/files/usr/lib/python3.12/site-packages/urllib3/connection.py", line 169, in _new_conn
    conn = connection.create_connection(
           ^^^^^^^^^^^^^^^^^^^^^^^^^^^^^
  File "/data/data/com.termux/files/usr/lib/python3.12/site-packages/urllib3/util/connection.py", line 73, in create_connection
    for res in socket.getaddrinfo(host, port, family, socket.SOCK_STREAM):
               ^^^^^^^^^^^^^^^^^^^^^^^^^^^^^^^^^^^^^^^^^^^^^^^^^^^^^^^^^^
  File "/data/data/com.termux/files/usr/lib/python3.12/socket.py", line 978, in getaddrinfo
    for res in _socket.getaddrinfo(host, port, family, type, proto, flags):
               ^^^^^^^^^^^^^^^^^^^^^^^^^^^^^^^^^^^^^^^^^^^^^^^^^^^^^^^^^^^
socket.gaierror: [Errno 7] No address associated with hostname

During handling of the above exception, another exception occurred:

Traceback (most recent call last):
  File "/data/data/com.termux/files/usr/lib/python3.12/site-packages/urllib3/connectionpool.py", line 699, in urlopen
    httplib_response = self._make_request(
                       ^^^^^^^^^^^^^^^^^^^
  File "/data/data/com.termux/files/usr/lib/python3.12/site-packages/urllib3/connectionpool.py", line 382, in _make_request
    self._validate_conn(conn)
  File "/data/data/com.termux/files/usr/lib/python3.12/site-packages/urllib3/connectionpool.py", line 1010, in _validate_conn
    conn.connect()
  File "/data/data/com.termux/files/usr/lib/python3.12/site-packages/urllib3/connection.py", line 353, in connect
    conn = self._new_conn()
           ^^^^^^^^^^^^^^^^
  File "/data/data/com.termux/files/usr/lib/python3.12/site-packages/urllib3/connection.py", line 181, in _new_conn
    raise NewConnectionError(
urllib3.exceptions.NewConnectionError: <urllib3.connection.HTTPSConnection object at 0x7680a82990>: Failed to establish a new connection: [Errno 7] No address associated with hostname

During handling of the above exception, another exception occurred:

Traceback (most recent call last):
  File "/data/data/com.termux/files/usr/lib/python3.12/site-packages/requests/adapters.py", line 644, in send
    resp = conn.urlopen(
           ^^^^^^^^^^^^^
  File "/data/data/com.termux/files/usr/lib/python3.12/site-packages/urllib3/connectionpool.py", line 755, in urlopen
    retries = retries.increment(
              ^^^^^^^^^^^^^^^^^^
  File "/data/data/com.termux/files/usr/lib/python3.12/site-packages/urllib3/util/retry.py", line 574, in increment
    raise MaxRetryError(_pool, url, error or ResponseError(cause))
urllib3.exceptions.MaxRetryError: HTTPSConnectionPool(host='api.telegram.org', port=443): Max retries exceeded with url: /bot8485995133:***********************************/getMe (Caused by NewConnectionError('<urllib3.connection.HTTPSConnection object at 0x7680a82990>: Failed to establish a new connection: [Errno 7] No address associated with hostname'))

During handling of the above exception, another exception occurred:

Traceback (most recent call last):
  File "/data/data/com.termux/files/usr/lib/python3.12/site-packages/telebot/__init__.py", line 1110, in infinity_polling
    self.polling(non_stop=True, timeout=timeout, long_polling_timeout=long_polling_timeout,
  File "/data/data/com.termux/files/usr/lib/python3.12/site-packages/telebot/__init__.py", line 1195, in polling
    logger.info('Starting your bot with username: [@%s]', self.user.username)
                                                          ^^^^^^^^^
  File "/data/data/com.termux/files/usr/lib/python3.12/site-packages/telebot/__init__.py", line 306, in user
    self._user = self.get_me()
                 ^^^^^^^^^^^^^
  File "/data/data/com.termux/files/usr/lib/python3.12/site-packages/telebot/__init__.py", line 1382, in get_me
    apihelper.get_me(self.token)
  File "/data/data/com.termux/files/usr/lib/python3.12/site-packages/telebot/apihelper.py", line 202, in get_me
    return _make_request(token, method_url)
           ^^^^^^^^^^^^^^^^^^^^^^^^^^^^^^^^
  File "/data/data/com.termux/files/usr/lib/python3.12/site-packages/telebot/apihelper.py", line 162, in _make_request
    result = _get_req_session().request(
             ^^^^^^^^^^^^^^^^^^^^^^^^^^^
  File "/data/data/com.termux/files/usr/lib/python3.12/site-packages/requests/sessions.py", line 589, in request
    resp = self.send(prep, **send_kwargs)
           ^^^^^^^^^^^^^^^^^^^^^^^^^^^^^^
  File "/data/data/com.termux/files/usr/lib/python3.12/site-packages/requests/sessions.py", line 703, in send
    r = adapter.send(request, **kwargs)
        ^^^^^^^^^^^^^^^^^^^^^^^^^^^^^^^
  File "/data/data/com.termux/files/usr/lib/python3.12/site-packages/requests/adapters.py", line 677, in send
    raise ConnectionError(e, request=request)
requests.exceptions.ConnectionError: HTTPSConnectionPool(host='api.telegram.org', port=443): Max retries exceeded with url: /bot8485995133:***********************************/getMe (Caused by NewConnectionError('<urllib3.connection.HTTPSConnection object at 0x7680a82990>: Failed to establish a new connection: [Errno 7] No address associated with hostname'))
"
2025-09-05 12:12:45,343 (__init__.py:1115 MainThread) ERROR - TeleBot: "Infinity polling exception: HTTPSConnectionPool(host='api.telegram.org', port=443): Max retries exceeded with url: /bot8485995133:***********************************/getMe (Caused by NewConnectionError('<urllib3.connection.HTTPSConnection object at 0x7913f97b00>: Failed to establish a new connection: [Errno 7] No address associated with hostname'))"
2025-09-05 12:12:45,430 (__init__.py:1117 MainThread) ERROR - TeleBot: "Exception traceback:
Traceback (most recent call last):
  File "/data/data/com.termux/files/usr/lib/python3.12/site-packages/urllib3/connection.py", line 169, in _new_conn
    conn = connection.create_connection(
           ^^^^^^^^^^^^^^^^^^^^^^^^^^^^^
  File "/data/data/com.termux/files/usr/lib/python3.12/site-packages/urllib3/util/connection.py", line 73, in create_connection
    for res in socket.getaddrinfo(host, port, family, socket.SOCK_STREAM):
               ^^^^^^^^^^^^^^^^^^^^^^^^^^^^^^^^^^^^^^^^^^^^^^^^^^^^^^^^^^
  File "/data/data/com.termux/files/usr/lib/python3.12/socket.py", line 978, in getaddrinfo
    for res in _socket.getaddrinfo(host, port, family, type, proto, flags):
               ^^^^^^^^^^^^^^^^^^^^^^^^^^^^^^^^^^^^^^^^^^^^^^^^^^^^^^^^^^^
socket.gaierror: [Errno 7] No address associated with hostname

During handling of the above exception, another exception occurred:

Traceback (most recent call last):
  File "/data/data/com.termux/files/usr/lib/python3.12/site-packages/urllib3/connectionpool.py", line 699, in urlopen
    httplib_response = self._make_request(
                       ^^^^^^^^^^^^^^^^^^^
  File "/data/data/com.termux/files/usr/lib/python3.12/site-packages/urllib3/connectionpool.py", line 382, in _make_request
    self._validate_conn(conn)
  File "/data/data/com.termux/files/usr/lib/python3.12/site-packages/urllib3/connectionpool.py", line 1010, in _validate_conn
    conn.connect()
  File "/data/data/com.termux/files/usr/lib/python3.12/site-packages/urllib3/connection.py", line 353, in connect
    conn = self._new_conn()
           ^^^^^^^^^^^^^^^^
  File "/data/data/com.termux/files/usr/lib/python3.12/site-packages/urllib3/connection.py", line 181, in _new_conn
    raise NewConnectionError(
urllib3.exceptions.NewConnectionError: <urllib3.connection.HTTPSConnection object at 0x7913f97b00>: Failed to establish a new connection: [Errno 7] No address associated with hostname

During handling of the above exception, another exception occurred:

Traceback (most recent call last):
  File "/data/data/com.termux/files/usr/lib/python3.12/site-packages/requests/adapters.py", line 644, in send
    resp = conn.urlopen(
           ^^^^^^^^^^^^^
  File "/data/data/com.termux/files/usr/lib/python3.12/site-packages/urllib3/connectionpool.py", line 755, in urlopen
    retries = retries.increment(
              ^^^^^^^^^^^^^^^^^^
  File "/data/data/com.termux/files/usr/lib/python3.12/site-packages/urllib3/util/retry.py", line 574, in increment
    raise MaxRetryError(_pool, url, error or ResponseError(cause))
urllib3.exceptions.MaxRetryError: HTTPSConnectionPool(host='api.telegram.org', port=443): Max retries exceeded with url: /bot8485995133:***********************************/getMe (Caused by NewConnectionError('<urllib3.connection.HTTPSConnection object at 0x7913f97b00>: Failed to establish a new connection: [Errno 7] No address associated with hostname'))

During handling of the above exception, another exception occurred:

Traceback (most recent call last):
  File "/data/data/com.termux/files/usr/lib/python3.12/site-packages/telebot/__init__.py", line 1110, in infinity_polling
    self.polling(non_stop=True, timeout=timeout, long_polling_timeout=long_polling_timeout,
  File "/data/data/com.termux/files/usr/lib/python3.12/site-packages/telebot/__init__.py", line 1195, in polling
    logger.info('Starting your bot with username: [@%s]', self.user.username)
                                                          ^^^^^^^^^
  File "/data/data/com.termux/files/usr/lib/python3.12/site-packages/telebot/__init__.py", line 306, in user
    self._user = self.get_me()
                 ^^^^^^^^^^^^^
  File "/data/data/com.termux/files/usr/lib/python3.12/site-packages/telebot/__init__.py", line 1382, in get_me
    apihelper.get_me(self.token)
  File "/data/data/com.termux/files/usr/lib/python3.12/site-packages/telebot/apihelper.py", line 202, in get_me
    return _make_request(token, method_url)
           ^^^^^^^^^^^^^^^^^^^^^^^^^^^^^^^^
  File "/data/data/com.termux/files/usr/lib/python3.12/site-packages/telebot/apihelper.py", line 162, in _make_request
    result = _get_req_session().request(
             ^^^^^^^^^^^^^^^^^^^^^^^^^^^
  File "/data/data/com.termux/files/usr/lib/python3.12/site-packages/requests/sessions.py", line 589, in request
    resp = self.send(prep, **send_kwargs)
           ^^^^^^^^^^^^^^^^^^^^^^^^^^^^^^
  File "/data/data/com.termux/files/usr/lib/python3.12/site-packages/requests/sessions.py", line 703, in send
    r = adapter.send(request, **kwargs)
        ^^^^^^^^^^^^^^^^^^^^^^^^^^^^^^^
  File "/data/data/com.termux/files/usr/lib/python3.12/site-packages/requests/adapters.py", line 677, in send
    raise ConnectionError(e, request=request)
requests.exceptions.ConnectionError: HTTPSConnectionPool(host='api.telegram.org', port=443): Max retries exceeded with url: /bot8485995133:***********************************/getMe (Caused by NewConnectionError('<urllib3.connection.HTTPSConnection object at 0x7913f97b00>: Failed to establish a new connection: [Errno 7] No address associated with hostname'))
"
